<?xml version="1.0"?>
<robot xmlns:xacro="http://www.ros.org/wiki/xacro">
  
  <xacro:property name="base_width" value="0.3"/>
  <xacro:property name="base_length" value="0.5"/>
  <xacro:property name="base_height" value="0.15"/>
  <xacro:property name="wheel_radius" value="0.08"/>
  <xacro:property name="wheel_width" value="0.04"/>
  <xacro:property name="wheel_separation" value="0.34"/>
  
  <xacro:macro name="wheel" params="prefix reflect">
    <link name="${prefix}_wheel">
      <visual>
        <origin xyz="0 0 0" rpy="1.5707 0 0"/>
        <geometry>
          <cylinder radius="${wheel_radius}" length="${wheel_width}"/>
        </geometry>
        <material name="black"/>
      </visual>
      <collision>
        <origin xyz="0 0 0" rpy="1.5707 0 0"/>
        <geometry>
          <cylinder radius="${wheel_radius}" length="${wheel_width}"/>
        </geometry>
      </collision>
      <inertial>
        <origin xyz="0 0 0" rpy="1.5707 0 0"/>
        <mass value="0.5"/>
        <inertia ixx="0.00107" ixy="0.0" ixz="0.0"
                 iyy="0.00107" iyz="0.0"
                 izz="0.0016"/>
      </inertial>
    </link>
    
    <joint name="${prefix}_wheel_joint" type="continuous">
      <parent link="base_link"/>
      <child link="${prefix}_wheel"/>
      <origin xyz="0 ${reflect*wheel_separation/2} ${-base_height/2+wheel_radius*0.3}" rpy="0 0 0"/>
      <axis xyz="0 1 0"/>
    </joint>
  </xacro:macro>
  
  <xacro:macro name="robot_base">
    <link name="base_footprint"/>
    
    <joint name="base_joint" type="fixed">
      <parent link="base_footprint"/>
      <child link="base_link"/>
      <origin xyz="0 0 ${wheel_radius}" rpy="0 0 0"/>
    </joint>
    
    <link name="base_link">
      <visual>
        <origin xyz="0 0 0" rpy="0 0 0"/>
        <geometry>
          <box size="${base_length} ${base_width} ${base_height}"/>
        </geometry>
        <material name="blue"/>
      </visual>
      <collision>
        <origin xyz="0 0 0" rpy="0 0 0"/>
        <geometry>
          <box size="${base_length} ${base_width} ${base_height}"/>
        </geometry>
      </collision>
      <inertial>
        <origin xyz="0 0 0" rpy="0 0 0"/>
        <mass value="5.0"/>
        <inertia ixx="${5.0/12*(base_width*base_width+base_height*base_height)}" ixy="0.0" ixz="0.0"
                 iyy="${5.0/12*(base_length*base_length+base_height*base_height)}" iyz="0.0"
                 izz="${5.0/12*(base_length*base_length+base_width*base_width)}"/>
      </inertial>
    </link>
    
    <xacro:wheel prefix="left" reflect="1"/>
    <xacro:wheel prefix="right" reflect="-1"/>
    
    <link name="front_caster">
      <visual>
        <origin xyz="0 0 0" rpy="0 0 0"/>
        <geometry>
          <sphere radius="0.03"/>
        </geometry>
        <material name="gray"/>
      </visual>
      <collision>
        <origin xyz="0 0 0" rpy="0 0 0"/>
        <geometry>
          <sphere radius="0.03"/>
        </geometry>
      </collision>
      <inertial>
        <origin xyz="0 0 0" rpy="0 0 0"/>
        <mass value="0.1"/>
        <inertia ixx="0.00004" ixy="0.0" ixz="0.0"
                 iyy="0.00004" iyz="0.0"
                 izz="0.00004"/>
      </inertial>
    </link>
    
    <joint name="front_caster_joint" type="fixed">
      <parent link="base_link"/>
      <child link="front_caster"/>
      <origin xyz="${base_length/2-0.05} 0 ${-base_height/2-0.045}" rpy="0 0 0"/>
    </joint>
  </xacro:macro>
  
</robot>
